[2024-01-08T11:18:30.087+0100] {taskinstance.py:1159} INFO - Dependencies all met for dep_context=non-requeueable deps ti=<TaskInstance: load_data_dag.load_data manual__2024-01-08T10:17:50.686017+00:00 [queued]>
[2024-01-08T11:18:30.091+0100] {taskinstance.py:1159} INFO - Dependencies all met for dep_context=requeueable deps ti=<TaskInstance: load_data_dag.load_data manual__2024-01-08T10:17:50.686017+00:00 [queued]>
[2024-01-08T11:18:30.092+0100] {taskinstance.py:1361} INFO - Starting attempt 1 of 1
[2024-01-08T11:18:30.103+0100] {taskinstance.py:1382} INFO - Executing <Task(SnowflakeOperator): load_data> on 2024-01-08 10:17:50.686017+00:00
[2024-01-08T11:18:30.105+0100] {standard_task_runner.py:57} INFO - Started process 83018 to run task
[2024-01-08T11:18:30.107+0100] {standard_task_runner.py:84} INFO - Running: ['airflow', 'tasks', 'run', 'load_data_dag', 'load_data', 'manual__2024-01-08T10:17:50.686017+00:00', '--job-id', '14', '--raw', '--subdir', 'DAGS_FOLDER/load_data.py', '--cfg-path', '/tmp/tmp4419xv1y']
[2024-01-08T11:18:30.108+0100] {standard_task_runner.py:85} INFO - Job 14: Subtask load_data
[2024-01-08T11:18:30.127+0100] {task_command.py:416} INFO - Running <TaskInstance: load_data_dag.load_data manual__2024-01-08T10:17:50.686017+00:00 [running]> on host DESKTOP-9ILQL7F.
[2024-01-08T11:18:30.146+0100] {abstractoperator.py:709} ERROR - Exception rendering Jinja template for task 'load_data', field 'sql'. Template: 'load_data.sql'
Traceback (most recent call last):
  File "/home/igor/.venv/lib/python3.10/site-packages/airflow/models/abstractoperator.py", line 701, in _do_render_template_fields
    rendered_content = self.render_template(
  File "/home/igor/.venv/lib/python3.10/site-packages/airflow/template/templater.py", line 152, in render_template
    template = jinja_env.get_template(value)
  File "/home/igor/.venv/lib/python3.10/site-packages/jinja2/environment.py", line 1010, in get_template
    return self._load_template(name, globals)
  File "/home/igor/.venv/lib/python3.10/site-packages/jinja2/environment.py", line 969, in _load_template
    template = self.loader.load(self, name, self.make_globals(globals))
  File "/home/igor/.venv/lib/python3.10/site-packages/jinja2/loaders.py", line 126, in load
    source, filename, uptodate = self.get_source(environment, name)
  File "/home/igor/.venv/lib/python3.10/site-packages/jinja2/loaders.py", line 218, in get_source
    raise TemplateNotFound(template)
jinja2.exceptions.TemplateNotFound: load_data.sql
[2024-01-08T11:18:30.150+0100] {taskinstance.py:1937} ERROR - Task failed with exception
Traceback (most recent call last):
  File "/home/igor/.venv/lib/python3.10/site-packages/airflow/models/taskinstance.py", line 1518, in _run_raw_task
    self._execute_task_with_callbacks(context, test_mode, session=session)
  File "/home/igor/.venv/lib/python3.10/site-packages/airflow/models/taskinstance.py", line 1647, in _execute_task_with_callbacks
    task_orig = self.render_templates(context=context)
  File "/home/igor/.venv/lib/python3.10/site-packages/airflow/models/taskinstance.py", line 2285, in render_templates
    original_task.render_template_fields(context)
  File "/home/igor/.venv/lib/python3.10/site-packages/airflow/models/baseoperator.py", line 1243, in render_template_fields
    self._do_render_template_fields(self, self.template_fields, context, jinja_env, set())
  File "/home/igor/.venv/lib/python3.10/site-packages/airflow/utils/session.py", line 79, in wrapper
    return func(*args, session=session, **kwargs)
  File "/home/igor/.venv/lib/python3.10/site-packages/airflow/models/abstractoperator.py", line 701, in _do_render_template_fields
    rendered_content = self.render_template(
  File "/home/igor/.venv/lib/python3.10/site-packages/airflow/template/templater.py", line 152, in render_template
    template = jinja_env.get_template(value)
  File "/home/igor/.venv/lib/python3.10/site-packages/jinja2/environment.py", line 1010, in get_template
    return self._load_template(name, globals)
  File "/home/igor/.venv/lib/python3.10/site-packages/jinja2/environment.py", line 969, in _load_template
    template = self.loader.load(self, name, self.make_globals(globals))
  File "/home/igor/.venv/lib/python3.10/site-packages/jinja2/loaders.py", line 126, in load
    source, filename, uptodate = self.get_source(environment, name)
  File "/home/igor/.venv/lib/python3.10/site-packages/jinja2/loaders.py", line 218, in get_source
    raise TemplateNotFound(template)
jinja2.exceptions.TemplateNotFound: load_data.sql
[2024-01-08T11:18:30.153+0100] {taskinstance.py:1400} INFO - Marking task as FAILED. dag_id=load_data_dag, task_id=load_data, execution_date=20240108T101750, start_date=20240108T101830, end_date=20240108T101830
[2024-01-08T11:18:30.163+0100] {standard_task_runner.py:104} ERROR - Failed to execute job 14 for task load_data (load_data.sql; 83018)
[2024-01-08T11:18:30.176+0100] {local_task_job_runner.py:228} INFO - Task exited with return code 1
[2024-01-08T11:18:30.184+0100] {taskinstance.py:2778} INFO - 0 downstream tasks scheduled from follow-on schedule check
